Workbook
Name 小学校: 応募者入力!$E$55

Sheet はじめに
A1: 令和8年度 防火ポスター応募者入力・名札作成テンプレート
A3: 使い方
A5: 1 | B5: 「設定」シートで学校名・市町村名・学校種別を確認してください。
A6: 2 | B6: 「応募者入力」シートに、学年・氏名・ふりがなを入力してください。
A7: 3 | B7: ふりがなはカタカナで入力してください。未入力や重複は「確認」欄で表示されます。
A8: 4 | B8: 名札を印刷する場合は「名札印刷」シートの開始Noを変更してください。1ページに2名分表示されます。
A9: 5 | B9: 事務局提出時は、このExcelファイルをそのままメール添付してください。
A11: 注意事項
A12: ・入力欄以外は編集しないでください。様式が崩れると名札・名簿が正しく作成されない場合があります。
A13: ・氏名は賞状等に使用しますので、漢字・ふりがなを必ず確認してください。
A14: ・作品提出時は、名札を作品下段中央に貼付してください。

Sheet 応募者入力
A1: 防火ポスター応募者入力シート | AA1: 小1 | AB1: 中1
A2: ※学校側で入力する主な欄は「学年」「氏名」「ふりがな」です。 | AA2: 小2 | AB2: 中2
AA3: 小3 | AB3: 中4
A4: No | B4: 市町村名 | C4: 学校名 | D4: 学校種別 | E4: 学年 | F4: 氏名 | G4: ふりがな | H4: 備考 | I4: 確認 | J4: 名札表示 | AA4: 小4
A5: 1 | B5: =設定!$B$5 -> 大垣市 | C5: =設定!$B$6 -> 大垣市立静里小学校 | D5: =設定!$B$7 -> 小学校 | E5: 小2 | F5: 大垣 太郎 | G5: おおがき たろう | I5: =IF(OR(F5="",G5=""),"未入力","OK") -> OK | J5: =IF(I5="OK",F5&"（"&G5&"）","") -> 大垣 太郎（おおがき たろう） | AA5: 小5
A6: 2 | B6: =設定!$B$5 -> 大垣市 | C6: =設定!$B$6 -> 大垣市立静里小学校 | D6: =設定!$B$7 -> 小学校 | E6: 小2 | F6: 大垣 花子 | G6: おおがき はなこ | I6: =IF(OR(F6="",G6=""),"未入力","OK") -> OK | J6: =IF(I6="OK",F6&"（"&G6&"）","") -> 大垣 花子（おおがき はなこ） | AA6: 小6
A7: 3 | B7: =設定!$B$5 -> 大垣市 | C7: =設定!$B$6 -> 大垣市立静里小学校 | D7: =設定!$B$7 -> 小学校 | E7: 小3 | F7: 田中 恵子 | G7: たなか けいこ | I7: =IF(OR(F7="",G7=""),"未入力","OK") -> OK | J7: =IF(I7="OK",F7&"（"&G7&"）","") -> 田中 恵子（たなか けいこ）
A8: 4 | B8: =設定!$B$5 -> 大垣市 | C8: =設定!$B$6 -> 大垣市立静里小学校 | D8: =設定!$B$7 -> 小学校 | E8: 小5 | F8: 祈祷 なにがし | G8: きとう なにがし | I8: =IF(OR(F8="",G8=""),"未入力","OK") -> OK | J8: =IF(I8="OK",F8&"（"&G8&"）","") -> 祈祷 なにがし（きとう なにがし）
A9: 5 | B9: =設定!$B$5 -> 大垣市 | C9: =設定!$B$6 -> 大垣市立静里小学校 | D9: =設定!$B$7 -> 小学校 | E9: 小6 | F9: 宮川 つよし | G9: みやがわ つよし | I9: =IF(OR(F9="",G9=""),"未入力","OK") -> OK | J9: =IF(I9="OK",F9&"（"&G9&"）","") -> 宮川 つよし（みやがわ つよし）
A10: 6 | B10: =設定!$B$5 -> 大垣市 | C10: =設定!$B$6 -> 大垣市立静里小学校 | D10: =設定!$B$7 -> 小学校 | E10: 小6 | F10: テスト 太郎 | G10: てすと たろう | I10: =IF(OR(F10="",G10=""),"未入力","OK") -> OK | J10: =IF(I10="OK",F10&"（"&G10&"）","") -> テスト 太郎（てすと たろう）
A11: 7 | B11: =設定!$B$5 -> 大垣市 | C11: =設定!$B$6 -> 大垣市立静里小学校 | D11: =設定!$B$7 -> 小学校 | E11: 小1 | F11: 大島もとこ | G11: おおしま もとこ | I11: =IF(OR(F11="",G11=""),"未入力","OK") -> OK | J11: =IF(I11="OK",F11&"（"&G11&"）","") -> 大島もとこ（おおしま もとこ）
A12: 8 | B12: =設定!$B$5 -> 大垣市 | C12: =設定!$B$6 -> 大垣市立静里小学校 | D12: =設定!$B$7 -> 小学校 | I12: =IF(OR(F12="",G12=""),"未入力","OK") -> 未入力 | J12: =IF(I12="OK",F12&"（"&G12&"）","")
A13: 9 | B13: =設定!$B$5 -> 大垣市 | C13: =設定!$B$6 -> 大垣市立静里小学校 | D13: =設定!$B$7 -> 小学校 | I13: =IF(OR(F13="",G13=""),"未入力","OK") -> 未入力 | J13: =IF(I13="OK",F13&"（"&G13&"）","")
A14: 10 | B14: =設定!$B$5 -> 大垣市 | C14: =設定!$B$6 -> 大垣市立静里小学校 | D14: =設定!$B$7 -> 小学校 | I14: =IF(OR(F14="",G14=""),"未入力","OK") -> 未入力 | J14: =IF(I14="OK",F14&"（"&G14&"）","")
A15: 11 | B15: =設定!$B$5 -> 大垣市 | C15: =設定!$B$6 -> 大垣市立静里小学校 | D15: =設定!$B$7 -> 小学校 | I15: =IF(OR(F15="",G15=""),"未入力","OK") -> 未入力 | J15: =IF(I15="OK",F15&"（"&G15&"）","")
A16: 12 | B16: =設定!$B$5 -> 大垣市 | C16: =設定!$B$6 -> 大垣市立静里小学校 | D16: =設定!$B$7 -> 小学校 | I16: =IF(OR(F16="",G16=""),"未入力","OK") -> 未入力 | J16: =IF(I16="OK",F16&"（"&G16&"）","")
A17: 13 | B17: =設定!$B$5 -> 大垣市 | C17: =設定!$B$6 -> 大垣市立静里小学校 | D17: =設定!$B$7 -> 小学校 | I17: =IF(OR(F17="",G17=""),"未入力","OK") -> 未入力 | J17: =IF(I17="OK",F17&"（"&G17&"）","")
A18: 14 | B18: =設定!$B$5 -> 大垣市 | C18: =設定!$B$6 -> 大垣市立静里小学校 | D18: =設定!$B$7 -> 小学校 | I18: =IF(OR(F18="",G18=""),"未入力","OK") -> 未入力 | J18: =IF(I18="OK",F18&"（"&G18&"）","")
A19: 15 | B19: =設定!$B$5 -> 大垣市 | C19: =設定!$B$6 -> 大垣市立静里小学校 | D19: =設定!$B$7 -> 小学校 | I19: =IF(OR(F19="",G19=""),"未入力","OK") -> 未入力 | J19: =IF(I19="OK",F19&"（"&G19&"）","")
A20: 16 | B20: =設定!$B$5 -> 大垣市 | C20: =設定!$B$6 -> 大垣市立静里小学校 | D20: =設定!$B$7 -> 小学校 | I20: =IF(OR(F20="",G20=""),"未入力","OK") -> 未入力 | J20: =IF(I20="OK",F20&"（"&G20&"）","")
A21: 17 | B21: =設定!$B$5 -> 大垣市 | C21: =設定!$B$6 -> 大垣市立静里小学校 | D21: =設定!$B$7 -> 小学校 | I21: =IF(OR(F21="",G21=""),"未入力","OK") -> 未入力 | J21: =IF(I21="OK",F21&"（"&G21&"）","")
A22: 18 | B22: =設定!$B$5 -> 大垣市 | C22: =設定!$B$6 -> 大垣市立静里小学校 | D22: =設定!$B$7 -> 小学校 | I22: =IF(OR(F22="",G22=""),"未入力","OK") -> 未入力 | J22: =IF(I22="OK",F22&"（"&G22&"）","")
A23: 19 | B23: =設定!$B$5 -> 大垣市 | C23: =設定!$B$6 -> 大垣市立静里小学校 | D23: =設定!$B$7 -> 小学校 | I23: =IF(OR(F23="",G23=""),"未入力","OK") -> 未入力 | J23: =IF(I23="OK",F23&"（"&G23&"）","")
... A104: 100 | B104: =設定!$B$5 -> 大垣市 | C104: =設定!$B$6 -> 大垣市立静里小学校 | D104: =設定!$B$7 -> 小学校 | I104: =IF(OR(F104="",G104=""),"未入力","OK") -> 未入力 | J104: =IF(I104="OK",F104&"（"&G104&"）","")

Sheet 名札印刷
B2: のりしろ
B3: 市町村名 | C3: =IF(応募者入力!$F$5="","",応募者入力!$B$5) -> 大垣市
B4: （消防本部名） | C4: =IF(応募者入力!$F$5="","","(大垣消防組合)") -> (大垣消防組合)
B5: 学校名 | C5: =IF(応募者入力!$F$5="","",応募者入力!$C$5) -> 大垣市立静里小学校
B6: (少年消防クラブ名)
B7: 学年 | C7: =IF(応募者入力!$F$5="","",IFERROR(MID(応募者入力!$E$5,2,1)&"年生","")) -> 2年生
B8: （ふりがな） | C8: =IF(応募者入力!$F$5="","",応募者入力!$G$5) -> おおがき たろう
B9: 氏名 | C9: =IF(応募者入力!$F$5="","",応募者入力!$F$5) -> 大垣 太郎
B12: のりしろ
B13: 市町村名 | C13: =IF(応募者入力!$F$6="","",応募者入力!$B$6) -> 大垣市
B14: （消防本部名） | C14: =IF(応募者入力!$F$6="","","(大垣消防組合)") -> (大垣消防組合)
B15: 学校名 | C15: =IF(応募者入力!$F$6="","",応募者入力!$C$6) -> 大垣市立静里小学校
B16: (少年消防クラブ名)
B17: 学年 | C17: =IF(応募者入力!$F$6="","",IFERROR(MID(応募者入力!$E$6,2,1)&"年生","")) -> 2年生
B18: （ふりがな） | C18: =IF(応募者入力!$F$6="","",応募者入力!$G$6) -> おおがき はなこ
B19: 氏名 | C19: =IF(応募者入力!$F$6="","",応募者入力!$F$6) -> 大垣 花子
B22: のりしろ
B23: 市町村名 | C23: =IF(応募者入力!$F$7="","",応募者入力!$B$7) -> 大垣市
B24: （消防本部名） | C24: =IF(応募者入力!$F$7="","","(大垣消防組合)") -> (大垣消防組合)
B25: 学校名 | C25: =IF(応募者入力!$F$7="","",応募者入力!$C$7) -> 大垣市立静里小学校
B26: (少年消防クラブ名)
B27: 学年 | C27: =IF(応募者入力!$F$7="","",IFERROR(MID(応募者入力!$E$7,2,1)&"年生","")) -> 3年生
B28: （ふりがな） | C28: =IF(応募者入力!$F$7="","",応募者入力!$G$7) -> たなか けいこ
B29: 氏名 | C29: =IF(応募者入力!$F$7="","",応募者入力!$F$7) -> 田中 恵子
B32: のりしろ
B33: 市町村名 | C33: =IF(応募者入力!$F$8="","",応募者入力!$B$8) -> 大垣市
B34: （消防本部名） | C34: =IF(応募者入力!$F$8="","","(大垣消防組合)") -> (大垣消防組合)
B35: 学校名 | C35: =IF(応募者入力!$F$8="","",応募者入力!$C$8) -> 大垣市立静里小学校
B36: (少年消防クラブ名)
B37: 学年 | C37: =IF(応募者入力!$F$8="","",IFERROR(MID(応募者入力!$E$8,2,1)&"年生","")) -> 5年生
B38: （ふりがな） | C38: =IF(応募者入力!$F$8="","",応募者入力!$G$8) -> きとう なにがし
B39: 氏名 | C39: =IF(応募者入力!$F$8="","",応募者入力!$F$8) -> 祈祷 なにがし
B42: のりしろ
B43: 市町村名 | C43: =IF(応募者入力!$F$9="","",応募者入力!$B$9) -> 大垣市
B44: （消防本部名） | C44: =IF(応募者入力!$F$9="","","(大垣消防組合)") -> (大垣消防組合)
B45: 学校名 | C45: =IF(応募者入力!$F$9="","",応募者入力!$C$9) -> 大垣市立静里小学校
B46: (少年消防クラブ名)
B47: 学年 | C47: =IF(応募者入力!$F$9="","",IFERROR(MID(応募者入力!$E$9,2,1)&"年生","")) -> 6年生
B48: （ふりがな） | C48: =IF(応募者入力!$F$9="","",応募者入力!$G$9) -> みやがわ つよし
B49: 氏名 | C49: =IF(応募者入力!$F$9="","",応募者入力!$F$9) -> 宮川 つよし
...

Sheet 名簿
A1: 応募者名簿（事務局確認用）
A3: No | B3: 市町村名 | C3: 学校名 | D3: 学校種別 | E3: 学年 | F3: 氏名 | G3: ふりがな | H3: 確認
A4: =IF(応募者入力!F5="","",応募者入力!A5) -> 1 | B4: =IF(応募者入力!F5="","",応募者入力!B5) -> 大垣市 | C4: =IF(応募者入力!F5="","",応募者入力!C5) -> 大垣市立静里小学校 | D4: =IF(応募者入力!F5="","",応募者入力!D5) -> 小学校 | E4: =IF(応募者入力!F5="","",応募者入力!E5) -> 小2 | F4: =応募者入力!F5 -> 大垣 太郎 | G4: =応募者入力!G5 -> おおがき たろう | H4: =応募者入力!I5 -> OK
A5: =IF(応募者入力!F6="","",応募者入力!A6) -> 2 | B5: =IF(応募者入力!F6="","",応募者入力!B6) -> 大垣市 | C5: =IF(応募者入力!F6="","",応募者入力!C6) -> 大垣市立静里小学校 | D5: =IF(応募者入力!F6="","",応募者入力!D6) -> 小学校 | E5: =IF(応募者入力!F6="","",応募者入力!E6) -> 小2 | F5: =応募者入力!F6 -> 大垣 花子 | G5: =応募者入力!G6 -> おおがき はなこ | H5: =応募者入力!I6 -> OK
A6: =IF(応募者入力!F7="","",応募者入力!A7) -> 3 | B6: =IF(応募者入力!F7="","",応募者入力!B7) -> 大垣市 | C6: =IF(応募者入力!F7="","",応募者入力!C7) -> 大垣市立静里小学校 | D6: =IF(応募者入力!F7="","",応募者入力!D7) -> 小学校 | E6: =IF(応募者入力!F7="","",応募者入力!E7) -> 小3 | F6: =応募者入力!F7 -> 田中 恵子 | G6: =応募者入力!G7 -> たなか けいこ | H6: =応募者入力!I7 -> OK
A7: =IF(応募者入力!F8="","",応募者入力!A8) -> 4 | B7: =IF(応募者入力!F8="","",応募者入力!B8) -> 大垣市 | C7: =IF(応募者入力!F8="","",応募者入力!C8) -> 大垣市立静里小学校 | D7: =IF(応募者入力!F8="","",応募者入力!D8) -> 小学校 | E7: =IF(応募者入力!F8="","",応募者入力!E8) -> 小5 | F7: =応募者入力!F8 -> 祈祷 なにがし | G7: =応募者入力!G8 -> きとう なにがし | H7: =応募者入力!I8 -> OK
A8: =IF(応募者入力!F9="","",応募者入力!A9) -> 5 | B8: =IF(応募者入力!F9="","",応募者入力!B9) -> 大垣市 | C8: =IF(応募者入力!F9="","",応募者入力!C9) -> 大垣市立静里小学校 | D8: =IF(応募者入力!F9="","",応募者入力!D9) -> 小学校 | E8: =IF(応募者入力!F9="","",応募者入力!E9) -> 小6 | F8: =応募者入力!F9 -> 宮川 つよし | G8: =応募者入力!G9 -> みやがわ つよし | H8: =応募者入力!I9 -> OK
A9: =IF(応募者入力!F10="","",応募者入力!A10) -> 6 | B9: =IF(応募者入力!F10="","",応募者入力!B10) -> 大垣市 | C9: =IF(応募者入力!F10="","",応募者入力!C10) -> 大垣市立静里小学校 | D9: =IF(応募者入力!F10="","",応募者入力!D10) -> 小学校 | E9: =IF(応募者入力!F10="","",応募者入力!E10) -> 小6 | F9: =応募者入力!F10 -> テスト 太郎 | G9: =応募者入力!G10 -> てすと たろう | H9: =応募者入力!I10 -> OK
A10: =IF(応募者入力!F11="","",応募者入力!A11) -> 7 | B10: =IF(応募者入力!F11="","",応募者入力!B11) -> 大垣市 | C10: =IF(応募者入力!F11="","",応募者入力!C11) -> 大垣市立静里小学校 | D10: =IF(応募者入力!F11="","",応募者入力!D11) -> 小学校 | E10: =IF(応募者入力!F11="","",応募者入力!E11) -> 小1 | F10: =応募者入力!F11 -> 大島もとこ | G10: =応募者入力!G11 -> おおしま もとこ | H10: =応募者入力!I11 -> OK
A11: =IF(応募者入力!F12="","",応募者入力!A12) | B11: =IF(応募者入力!F12="","",応募者入力!B12) | C11: =IF(応募者入力!F12="","",応募者入力!C12) | D11: =IF(応募者入力!F12="","",応募者入力!D12) | E11: =IF(応募者入力!F12="","",応募者入力!E12) | F11: =応募者入力!F12 -> 0 | G11: =応募者入力!G12 -> 0 | H11: =応募者入力!I12 -> 未入力
A12: =IF(応募者入力!F13="","",応募者入力!A13) | B12: =IF(応募者入力!F13="","",応募者入力!B13) | C12: =IF(応募者入力!F13="","",応募者入力!C13) | D12: =IF(応募者入力!F13="","",応募者入力!D13) | E12: =IF(応募者入力!F13="","",応募者入力!E13) | F12: =応募者入力!F13 -> 0 | G12: =応募者入力!G13 -> 0 | H12: =応募者入力!I13 -> 未入力
A13: =IF(応募者入力!F14="","",応募者入力!A14) | B13: =IF(応募者入力!F14="","",応募者入力!B14) | C13: =IF(応募者入力!F14="","",応募者入力!C14) | D13: =IF(応募者入力!F14="","",応募者入力!D14) | E13: =IF(応募者入力!F14="","",応募者入力!E14) | F13: =応募者入力!F14 -> 0 | G13: =応募者入力!G14 -> 0 | H13: =応募者入力!I14 -> 未入力
A14: =IF(応募者入力!F15="","",応募者入力!A15) | B14: =IF(応募者入力!F15="","",応募者入力!B15) | C14: =IF(応募者入力!F15="","",応募者入力!C15) | D14: =IF(応募者入力!F15="","",応募者入力!D15) | E14: =IF(応募者入力!F15="","",応募者入力!E15) | F14: =応募者入力!F15 -> 0 | G14: =応募者入力!G15 -> 0 | H14: =応募者入力!I15 -> 未入力
A15: =IF(応募者入力!F16="","",応募者入力!A16) | B15: =IF(応募者入力!F16="","",応募者入力!B16) | C15: =IF(応募者入力!F16="","",応募者入力!C16) | D15: =IF(応募者入力!F16="","",応募者入力!D16) | E15: =IF(応募者入力!F16="","",応募者入力!E16) | F15: =応募者入力!F16 -> 0 | G15: =応募者入力!G16 -> 0 | H15: =応募者入力!I16 -> 未入力
... A84: =IF(応募者入力!F85="","",応募者入力!A85) | B84: =IF(応募者入力!F85="","",応募者入力!B85) | C84: =IF(応募者入力!F85="","",応募者入力!C85) | D84: =IF(応募者入力!F85="","",応募者入力!D85) | E84: =IF(応募者入力!F85="","",応募者入力!E85) | F84: =応募者入力!F85 -> 0 | G84: =応募者入力!G85 -> 0 | H84: =応募者入力!I85 -> 未入力

Sheet 集計
A1: 応募状況集計
A3: 区分 | B3: 学年 | C3: 応募点数 | D3: 未入力確認 | E3: 重複確認 | F3: 備考
A4: 小学校 | B4: 小1 | C4: =COUNTIF(応募者入力!$E$5:$E$54,B4) -> 1 | D4: =COUNTIFS(応募者入力!$E$5:$E$54,B4,応募者入力!$I$5:$I$54,"未入力あり") -> 0 | E4: =COUNTIFS(応募者入力!$E$5:$E$54,B4,応募者入力!$I$5:$I$54,"重複確認") -> 0
A5: 小学校 | B5: 小2 | C5: =COUNTIF(応募者入力!$E$5:$E$54,B5) -> 2 | D5: =COUNTIFS(応募者入力!$E$5:$E$54,B5,応募者入力!$I$5:$I$54,"未入力あり") -> 0 | E5: =COUNTIFS(応募者入力!$E$5:$E$54,B5,応募者入力!$I$5:$I$54,"重複確認") -> 0
A6: 小学校 | B6: 小3 | C6: =COUNTIF(応募者入力!$E$5:$E$54,B6) -> 1 | D6: =COUNTIFS(応募者入力!$E$5:$E$54,B6,応募者入力!$I$5:$I$54,"未入力あり") -> 0 | E6: =COUNTIFS(応募者入力!$E$5:$E$54,B6,応募者入力!$I$5:$I$54,"重複確認") -> 0
A7: 小学校 | B7: 小4 | C7: =COUNTIF(応募者入力!$E$5:$E$54,B7) -> 0 | D7: =COUNTIFS(応募者入力!$E$5:$E$54,B7,応募者入力!$I$5:$I$54,"未入力あり") -> 0 | E7: =COUNTIFS(応募者入力!$E$5:$E$54,B7,応募者入力!$I$5:$I$54,"重複確認") -> 0
A8: 小学校 | B8: 小5 | C8: =COUNTIF(応募者入力!$E$5:$E$54,B8) -> 1 | D8: =COUNTIFS(応募者入力!$E$5:$E$54,B8,応募者入力!$I$5:$I$54,"未入力あり") -> 0 | E8: =COUNTIFS(応募者入力!$E$5:$E$54,B8,応募者入力!$I$5:$I$54,"重複確認") -> 0
A9: 小学校 | B9: 小6 | C9: =COUNTIF(応募者入力!$E$5:$E$54,B9) -> 2 | D9: =COUNTIFS(応募者入力!$E$5:$E$54,B9,応募者入力!$I$5:$I$54,"未入力あり") -> 0 | E9: =COUNTIFS(応募者入力!$E$5:$E$54,B9,応募者入力!$I$5:$I$54,"重複確認") -> 0
A10: 中学校 | B10: 中1 | C10: =COUNTIF(応募者入力!$E$5:$E$54,B10) -> 0 | D10: =COUNTIFS(応募者入力!$E$5:$E$54,B10,応募者入力!$I$5:$I$54,"未入力あり") -> 0 | E10: =COUNTIFS(応募者入力!$E$5:$E$54,B10,応募者入力!$I$5:$I$54,"重複確認") -> 0
A11: 中学校 | B11: 中2 | C11: =COUNTIF(応募者入力!$E$5:$E$54,B11) -> 0 | D11: =COUNTIFS(応募者入力!$E$5:$E$54,B11,応募者入力!$I$5:$I$54,"未入力あり") -> 0 | E11: =COUNTIFS(応募者入力!$E$5:$E$54,B11,応募者入力!$I$5:$I$54,"重複確認") -> 0
A12: 中学校 | B12: 中3 | C12: =COUNTIF(応募者入力!$E$5:$E$54,B12) -> 0 | D12: =COUNTIFS(応募者入力!$E$5:$E$54,B12,応募者入力!$I$5:$I$54,"未入力あり") -> 0 | E12: =COUNTIFS(応募者入力!$E$5:$E$54,B12,応募者入力!$I$5:$I$54,"重複確認") -> 0
A13: 計 | C13: =SUM(C4:C12) -> 7 | D13: =SUM(D4:D12) -> 0 | E13: =SUM(E4:E12) -> 0
A15: 提出前チェック：D列・E列が0になっていることを確認してください。

Sheet 設定
A1: 設定
A3: 項目 | B3: 入力値 | C3: 説明 | D3: 備考 | F3: 学年候補
A4: 年度 | B4: 令和8年度 | C4: 募集年度 | F4: 小1
A5: 市町村名 | B5: 大垣市 | C5: 例：大垣市、神戸町、輪之内町、安八町、池田町 | D5: 名札に反映 | F5: 小2
A6: 学校名 | B6: 大垣市立静里小学校 | C6: 例：○○小学校、○○中学校 | D6: 名札・名簿に反映 | F6: 小3
A7: 学校種別 | B7: 小学校 | C7: 小学校または中学校を選択 | D7: 学年選択に使用 | F7: 小4
A8: 提出期限 | B8: 令和8年8月末予定 | C8: 必要に応じて変更 | F8: 小5
A9: 担当課 | B9: 大垣消防組合消防本部 予防課 | F9: 小6
F10: 中1
F11: 中2
F12: 中3
F13: 小学校
F14: 中学校

Sheet 使い方
A1: 防火ポスター応募・名札印刷ファイルの使い方
A3: 1 | B3: 「応募者入力」シートに、応募した児童生徒の市町村名、学校名、学校種別、学年、氏名、ふりがなを入力します。
A4: 2 | B4: 「名札印刷」シートを開き、必要なページ数を印刷します。1ページにつき1名分の名札が印刷されます。
A5: 3 | B5: 印刷した名札を切り取り、作品下段中央に貼付してください。
A6: 4 | B6: 応募者が100人未満の場合、空欄ページは印刷不要です。印刷時に必要なページまでを指定してください。
